Workbook

Sheet Leia-me
A1: Cardápio Artes da Pizza — Comparativo Multi-Canal
A2: Fonte: extração do portal iFood Parceiro (2025-06)
A4: COMO USAR
A6: 1. Aba Dados: fonte normalizada. Preencha as colunas em branco:
A7: - Preço Brotinho/Grande nas plataformas Loja (Retirada) e Keeta
A8: - Preço Grande no iFood (segundo tamanho de cada sabor)
A9: - As demais abas atualizam automaticamente.
A11: 2. Aba Comparativo: pivot lado-a-lado. Mostra diferenças R$/% iFood vs Loja
A12: e Keeta vs Loja, além do canal mais caro/barato por sabor.
A14: 3. Aba Margens: edite as taxas em B3:B5. O líquido é recalculado.
A15: Default: iFood 23%, Loja 0%, Keeta 18% — ajuste conforme contrato.
A17: 4. Aba Resumo: estatísticas por categoria e por canal.
... A27: - Sobremesa (Torta Holandesa): tamanho único R$ 14,90

Sheet Dados
A1: Categoria | B1: Sabor | C1: Tamanho | D1: Plataforma | E1: Preço
A2: Cabe no seu bolso!!! | B2: Atum especial com mussarela | C2: Brotinho | D2: iFood | E2: 88.9
A3: Cabe no seu bolso!!! | B3: Atum especial com mussarela | C3: Brotinho | D3: Loja (Retirada)
A4: Cabe no seu bolso!!! | B4: Atum especial com mussarela | C4: Brotinho | D4: Keeta
A5: Cabe no seu bolso!!! | B5: Atum especial com mussarela | C5: Grande | D5: iFood
A6: Cabe no seu bolso!!! | B6: Atum especial com mussarela | C6: Grande | D6: Loja (Retirada)
A7: Cabe no seu bolso!!! | B7: Atum especial com mussarela | C7: Grande | D7: Keeta
A8: Cabe no seu bolso!!! | B8: Atum ralado com mussarela | C8: Brotinho | D8: iFood | E8: 72.9
A9: Cabe no seu bolso!!! | B9: Atum ralado com mussarela | C9: Brotinho | D9: Loja (Retirada)
A10: Cabe no seu bolso!!! | B10: Atum ralado com mussarela | C10: Brotinho | D10: Keeta
A11: Cabe no seu bolso!!! | B11: Atum ralado com mussarela | C11: Grande | D11: iFood
A12: Cabe no seu bolso!!! | B12: Atum ralado com mussarela | C12: Grande | D12: Loja (Retirada)
A13: Cabe no seu bolso!!! | B13: Atum ralado com mussarela | C13: Grande | D13: Keeta
A14: Cabe no seu bolso!!! | B14: Pizza Atum | C14: Brotinho | D14: iFood | E14: 58.9
A15: Cabe no seu bolso!!! | B15: Pizza Atum | C15: Brotinho | D15: Loja (Retirada)
A16: Cabe no seu bolso!!! | B16: Pizza Atum | C16: Brotinho | D16: Keeta
A17: Cabe no seu bolso!!! | B17: Pizza Atum | C17: Grande | D17: iFood
A18: Cabe no seu bolso!!! | B18: Pizza Atum | C18: Grande | D18: Loja (Retirada)
A19: Cabe no seu bolso!!! | B19: Pizza Atum | C19: Grande | D19: Keeta
A20: Cabe no seu bolso!!! | B20: Pizza Lombo | C20: Brotinho | D20: iFood | E20: 58.9
A21: Cabe no seu bolso!!! | B21: Pizza Lombo | C21: Brotinho | D21: Loja (Retirada)
A22: Cabe no seu bolso!!! | B22: Pizza Lombo | C22: Brotinho | D22: Keeta
A23: Cabe no seu bolso!!! | B23: Pizza Lombo | C23: Grande | D23: iFood
A24: Cabe no seu bolso!!! | B24: Pizza Lombo | C24: Grande | D24: Loja (Retirada)
A25: Cabe no seu bolso!!! | B25: Pizza Lombo | C25: Grande | D25: Keeta
A26: Cabe no seu bolso!!! | B26: Pizza Mussarela | C26: Brotinho | D26: iFood | E26: 58.9
A27: Cabe no seu bolso!!! | B27: Pizza Mussarela | C27: Brotinho | D27: Loja (Retirada)
A28: Cabe no seu bolso!!! | B28: Pizza Mussarela | C28: Brotinho | D28: Keeta
A29: Cabe no seu bolso!!! | B29: Pizza Mussarela | C29: Grande | D29: iFood
A30: Cabe no seu bolso!!! | B30: Pizza Mussarela | C30: Grande | D30: Loja (Retirada)
A31: Cabe no seu bolso!!! | B31: Pizza Mussarela | C31: Grande | D31: Keeta
A32: Imperdíveis Pizzas salgadas | B32: Pizza Vegetariana | C32: Brotinho | D32: iFood | E32: 75.9
A33: Imperdíveis Pizzas salgadas | B33: Pizza Vegetariana | C33: Brotinho | D33: Loja (Retirada)
A34: Imperdíveis Pizzas salgadas | B34: Pizza Vegetariana | C34: Brotinho | D34: Keeta
A35: Imperdíveis Pizzas salgadas | B35: Pizza Vegetariana | C35: Grande | D35: iFood
A36: Imperdíveis Pizzas salgadas | B36: Pizza Vegetariana | C36: Grande | D36: Loja (Retirada)
A37: Imperdíveis Pizzas salgadas | B37: Pizza Vegetariana | C37: Grande | D37: Keeta
A38: Imperdíveis Pizzas salgadas | B38: Pizza Toscana | C38: Brotinho | D38: iFood | E38: 65.9
A39: Imperdíveis Pizzas salgadas | B39: Pizza Toscana | C39: Brotinho | D39: Loja (Retirada)
A40: Imperdíveis Pizzas salgadas | B40: Pizza Toscana | C40: Brotinho | D40: Keeta
...

Sheet Comparativo
A1: Categoria | B1: Sabor | C1: Tamanho | D1: iFood | E1: Loja (Retirada) | F1: Keeta | G1: iFood vs Loja (R$) | H1: iFood vs Loja (%) | I1: Keeta vs Loja (R$) | J1: Keeta vs Loja (%) | K1: Maior canal | L1: Menor canal
A2: Cabe no seu bolso!!! | B2: Atum especial com mussarela | C2: Brotinho | D2: =SUMIFS(Dados!$E:$E,Dados!$B:$B,$B2,Dados!$C:$C,$C2,Dados!$D:$D,"iFood") | E2: =SUMIFS(Dados!$E:$E,Dados!$B:$B,$B2,Dados!$C:$C,$C2,Dados!$D:$D,"Loja (Retirada)") | F2: =SUMIFS(Dados!$E:$E,Dados!$B:$B,$B2,Dados!$C:$C,$C2,Dados!$D:$D,"Keeta") | G2: =IFERROR(IF(E2=0,"",D2-E2),"") | H2: =IFERROR(IF(E2=0,"",(D2-E2)/E2),"") | I2: =IFERROR(IF(E2=0,"",F2-E2),"") | J2: =IFERROR(IF(E2=0,"",(F2-E2)/E2),"") | K2: =IFERROR(INDEX($D$1:$F$1,MATCH(MAX(D2:F2),D2:F2,0)),"") | L2: =IFERROR(INDEX($D$1:$F$1,MATCH(MIN(IF(D2:F2>0,D2:F2)),D2:F2,0)),"")
A3: Cabe no seu bolso!!! | B3: Atum especial com mussarela | C3: Grande | D3: =SUMIFS(Dados!$E:$E,Dados!$B:$B,$B3,Dados!$C:$C,$C3,Dados!$D:$D,"iFood") | E3: =SUMIFS(Dados!$E:$E,Dados!$B:$B,$B3,Dados!$C:$C,$C3,Dados!$D:$D,"Loja (Retirada)") | F3: =SUMIFS(Dados!$E:$E,Dados!$B:$B,$B3,Dados!$C:$C,$C3,Dados!$D:$D,"Keeta") | G3: =IFERROR(IF(E3=0,"",D3-E3),"") | H3: =IFERROR(IF(E3=0,"",(D3-E3)/E3),"") | I3: =IFERROR(IF(E3=0,"",F3-E3),"") | J3: =IFERROR(IF(E3=0,"",(F3-E3)/E3),"") | K3: =IFERROR(INDEX($D$1:$F$1,MATCH(MAX(D3:F3),D3:F3,0)),"") | L3: =IFERROR(INDEX($D$1:$F$1,MATCH(MIN(IF(D3:F3>0,D3:F3)),D3:F3,0)),"")
A4: Cabe no seu bolso!!! | B4: Atum ralado com mussarela | C4: Brotinho | D4: =SUMIFS(Dados!$E:$E,Dados!$B:$B,$B4,Dados!$C:$C,$C4,Dados!$D:$D,"iFood") | E4: =SUMIFS(Dados!$E:$E,Dados!$B:$B,$B4,Dados!$C:$C,$C4,Dados!$D:$D,"Loja (Retirada)") | F4: =SUMIFS(Dados!$E:$E,Dados!$B:$B,$B4,Dados!$C:$C,$C4,Dados!$D:$D,"Keeta") | G4: =IFERROR(IF(E4=0,"",D4-E4),"") | H4: =IFERROR(IF(E4=0,"",(D4-E4)/E4),"") | I4: =IFERROR(IF(E4=0,"",F4-E4),"") | J4: =IFERROR(IF(E4=0,"",(F4-E4)/E4),"") | K4: =IFERROR(INDEX($D$1:$F$1,MATCH(MAX(D4:F4),D4:F4,0)),"") | L4: =IFERROR(INDEX($D$1:$F$1,MATCH(MIN(IF(D4:F4>0,D4:F4)),D4:F4,0)),"")
A5: Cabe no seu bolso!!! | B5: Atum ralado com mussarela | C5: Grande | D5: =SUMIFS(Dados!$E:$E,Dados!$B:$B,$B5,Dados!$C:$C,$C5,Dados!$D:$D,"iFood") | E5: =SUMIFS(Dados!$E:$E,Dados!$B:$B,$B5,Dados!$C:$C,$C5,Dados!$D:$D,"Loja (Retirada)") | F5: =SUMIFS(Dados!$E:$E,Dados!$B:$B,$B5,Dados!$C:$C,$C5,Dados!$D:$D,"Keeta") | G5: =IFERROR(IF(E5=0,"",D5-E5),"") | H5: =IFERROR(IF(E5=0,"",(D5-E5)/E5),"") | I5: =IFERROR(IF(E5=0,"",F5-E5),"") | J5: =IFERROR(IF(E5=0,"",(F5-E5)/E5),"") | K5: =IFERROR(INDEX($D$1:$F$1,MATCH(MAX(D5:F5),D5:F5,0)),"") | L5: =IFERROR(INDEX($D$1:$F$1,MATCH(MIN(IF(D5:F5>0,D5:F5)),D5:F5,0)),"")
A6: Cabe no seu bolso!!! | B6: Pizza Atum | C6: Brotinho | D6: =SUMIFS(Dados!$E:$E,Dados!$B:$B,$B6,Dados!$C:$C,$C6,Dados!$D:$D,"iFood") | E6: =SUMIFS(Dados!$E:$E,Dados!$B:$B,$B6,Dados!$C:$C,$C6,Dados!$D:$D,"Loja (Retirada)") | F6: =SUMIFS(Dados!$E:$E,Dados!$B:$B,$B6,Dados!$C:$C,$C6,Dados!$D:$D,"Keeta") | G6: =IFERROR(IF(E6=0,"",D6-E6),"") | H6: =IFERROR(IF(E6=0,"",(D6-E6)/E6),"") | I6: =IFERROR(IF(E6=0,"",F6-E6),"") | J6: =IFERROR(IF(E6=0,"",(F6-E6)/E6),"") | K6: =IFERROR(INDEX($D$1:$F$1,MATCH(MAX(D6:F6),D6:F6,0)),"") | L6: =IFERROR(INDEX($D$1:$F$1,MATCH(MIN(IF(D6:F6>0,D6:F6)),D6:F6,0)),"")
A7: Cabe no seu bolso!!! | B7: Pizza Atum | C7: Grande | D7: =SUMIFS(Dados!$E:$E,Dados!$B:$B,$B7,Dados!$C:$C,$C7,Dados!$D:$D,"iFood") | E7: =SUMIFS(Dados!$E:$E,Dados!$B:$B,$B7,Dados!$C:$C,$C7,Dados!$D:$D,"Loja (Retirada)") | F7: =SUMIFS(Dados!$E:$E,Dados!$B:$B,$B7,Dados!$C:$C,$C7,Dados!$D:$D,"Keeta") | G7: =IFERROR(IF(E7=0,"",D7-E7),"") | H7: =IFERROR(IF(E7=0,"",(D7-E7)/E7),"") | I7: =IFERROR(IF(E7=0,"",F7-E7),"") | J7: =IFERROR(IF(E7=0,"",(F7-E7)/E7),"") | K7: =IFERROR(INDEX($D$1:$F$1,MATCH(MAX(D7:F7),D7:F7,0)),"") | L7: =IFERROR(INDEX($D$1:$F$1,MATCH(MIN(IF(D7:F7>0,D7:F7)),D7:F7,0)),"")
A8: Cabe no seu bolso!!! | B8: Pizza Lombo | C8: Brotinho | D8: =SUMIFS(Dados!$E:$E,Dados!$B:$B,$B8,Dados!$C:$C,$C8,Dados!$D:$D,"iFood") | E8: =SUMIFS(Dados!$E:$E,Dados!$B:$B,$B8,Dados!$C:$C,$C8,Dados!$D:$D,"Loja (Retirada)") | F8: =SUMIFS(Dados!$E:$E,Dados!$B:$B,$B8,Dados!$C:$C,$C8,Dados!$D:$D,"Keeta") | G8: =IFERROR(IF(E8=0,"",D8-E8),"") | H8: =IFERROR(IF(E8=0,"",(D8-E8)/E8),"") | I8: =IFERROR(IF(E8=0,"",F8-E8),"") | J8: =IFERROR(IF(E8=0,"",(F8-E8)/E8),"") | K8: =IFERROR(INDEX($D$1:$F$1,MATCH(MAX(D8:F8),D8:F8,0)),"") | L8: =IFERROR(INDEX($D$1:$F$1,MATCH(MIN(IF(D8:F8>0,D8:F8)),D8:F8,0)),"")
A9: Cabe no seu bolso!!! | B9: Pizza Lombo | C9: Grande | D9: =SUMIFS(Dados!$E:$E,Dados!$B:$B,$B9,Dados!$C:$C,$C9,Dados!$D:$D,"iFood") | E9: =SUMIFS(Dados!$E:$E,Dados!$B:$B,$B9,Dados!$C:$C,$C9,Dados!$D:$D,"Loja (Retirada)") | F9: =SUMIFS(Dados!$E:$E,Dados!$B:$B,$B9,Dados!$C:$C,$C9,Dados!$D:$D,"Keeta") | G9: =IFERROR(IF(E9=0,"",D9-E9),"") | H9: =IFERROR(IF(E9=0,"",(D9-E9)/E9),"") | I9: =IFERROR(IF(E9=0,"",F9-E9),"") | J9: =IFERROR(IF(E9=0,"",(F9-E9)/E9),"") | K9: =IFERROR(INDEX($D$1:$F$1,MATCH(MAX(D9:F9),D9:F9,0)),"") | L9: =IFERROR(INDEX($D$1:$F$1,MATCH(MIN(IF(D9:F9>0,D9:F9)),D9:F9,0)),"")
A10: Cabe no seu bolso!!! | B10: Pizza Mussarela | C10: Brotinho | D10: =SUMIFS(Dados!$E:$E,Dados!$B:$B,$B10,Dados!$C:$C,$C10,Dados!$D:$D,"iFood") | E10: =SUMIFS(Dados!$E:$E,Dados!$B:$B,$B10,Dados!$C:$C,$C10,Dados!$D:$D,"Loja (Retirada)") | F10: =SUMIFS(Dados!$E:$E,Dados!$B:$B,$B10,Dados!$C:$C,$C10,Dados!$D:$D,"Keeta") | G10: =IFERROR(IF(E10=0,"",D10-E10),"") | H10: =IFERROR(IF(E10=0,"",(D10-E10)/E10),"") | I10: =IFERROR(IF(E10=0,"",F10-E10),"") | J10: =IFERROR(IF(E10=0,"",(F10-E10)/E10),"") | K10: =IFERROR(INDEX($D$1:$F$1,MATCH(MAX(D10:F10),D10:F10,0)),"") | L10: =IFERROR(INDEX($D$1:$F$1,MATCH(MIN(IF(D10:F10>0,D10:F10)),D10:F10,0)),"")
A11: Cabe no seu bolso!!! | B11: Pizza Mussarela | C11: Grande | D11: =SUMIFS(Dados!$E:$E,Dados!$B:$B,$B11,Dados!$C:$C,$C11,Dados!$D:$D,"iFood") | E11: =SUMIFS(Dados!$E:$E,Dados!$B:$B,$B11,Dados!$C:$C,$C11,Dados!$D:$D,"Loja (Retirada)") | F11: =SUMIFS(Dados!$E:$E,Dados!$B:$B,$B11,Dados!$C:$C,$C11,Dados!$D:$D,"Keeta") | G11: =IFERROR(IF(E11=0,"",D11-E11),"") | H11: =IFERROR(IF(E11=0,"",(D11-E11)/E11),"") | I11: =IFERROR(IF(E11=0,"",F11-E11),"") | J11: =IFERROR(IF(E11=0,"",(F11-E11)/E11),"") | K11: =IFERROR(INDEX($D$1:$F$1,MATCH(MAX(D11:F11),D11:F11,0)),"") | L11: =IFERROR(INDEX($D$1:$F$1,MATCH(MIN(IF(D11:F11>0,D11:F11)),D11:F11,0)),"")
A12: Imperdíveis Pizzas salgadas | B12: Pizza Vegetariana | C12: Brotinho | D12: =SUMIFS(Dados!$E:$E,Dados!$B:$B,$B12,Dados!$C:$C,$C12,Dados!$D:$D,"iFood") | E12: =SUMIFS(Dados!$E:$E,Dados!$B:$B,$B12,Dados!$C:$C,$C12,Dados!$D:$D,"Loja (Retirada)") | F12: =SUMIFS(Dados!$E:$E,Dados!$B:$B,$B12,Dados!$C:$C,$C12,Dados!$D:$D,"Keeta") | G12: =IFERROR(IF(E12=0,"",D12-E12),"") | H12: =IFERROR(IF(E12=0,"",(D12-E12)/E12),"") | I12: =IFERROR(IF(E12=0,"",F12-E12),"") | J12: =IFERROR(IF(E12=0,"",(F12-E12)/E12),"") | K12: =IFERROR(INDEX($D$1:$F$1,MATCH(MAX(D12:F12),D12:F12,0)),"") | L12: =IFERROR(INDEX($D$1:$F$1,MATCH(MIN(IF(D12:F12>0,D12:F12)),D12:F12,0)),"")
A13: Imperdíveis Pizzas salgadas | B13: Pizza Vegetariana | C13: Grande | D13: =SUMIFS(Dados!$E:$E,Dados!$B:$B,$B13,Dados!$C:$C,$C13,Dados!$D:$D,"iFood") | E13: =SUMIFS(Dados!$E:$E,Dados!$B:$B,$B13,Dados!$C:$C,$C13,Dados!$D:$D,"Loja (Retirada)") | F13: =SUMIFS(Dados!$E:$E,Dados!$B:$B,$B13,Dados!$C:$C,$C13,Dados!$D:$D,"Keeta") | G13: =IFERROR(IF(E13=0,"",D13-E13),"") | H13: =IFERROR(IF(E13=0,"",(D13-E13)/E13),"") | I13: =IFERROR(IF(E13=0,"",F13-E13),"") | J13: =IFERROR(IF(E13=0,"",(F13-E13)/E13),"") | K13: =IFERROR(INDEX($D$1:$F$1,MATCH(MAX(D13:F13),D13:F13,0)),"") | L13: =IFERROR(INDEX($D$1:$F$1,MATCH(MIN(IF(D13:F13>0,D13:F13)),D13:F13,0)),"")
... A148: Incrível Sobremesa | B148: Torta Holandesa | C148: Único | D148: =SUMIFS(Dados!$E:$E,Dados!$B:$B,$B148,Dados!$C:$C,$C148,Dados!$D:$D,"iFood") | E148: =SUMIFS(Dados!$E:$E,Dados!$B:$B,$B148,Dados!$C:$C,$C148,Dados!$D:$D,"Loja (Retirada)") | F148: =SUMIFS(Dados!$E:$E,Dados!$B:$B,$B148,Dados!$C:$C,$C148,Dados!$D:$D,"Keeta") | G148: =IFERROR(IF(E148=0,"",D148-E148),"") | H148: =IFERROR(IF(E148=0,"",(D148-E148)/E148),"") | I148: =IFERROR(IF(E148=0,"",F148-E148),"") | J148: =IFERROR(IF(E148=0,"",(F148-E148)/E148),"") | K148: =IFERROR(INDEX($D$1:$F$1,MATCH(MAX(D148:F148),D148:F148,0)),"") | L148: =IFERROR(INDEX($D$1:$F$1,MATCH(MIN(IF(D148:F148>0,D148:F148)),D148:F148,0)),"")

Sheet Margens
A1: Configuração de taxas | K1: Edite B3:B5 (taxas) para recalcular automaticamente todos os líquidos.
A2: Canal | B2: Taxa (%) | C2: Repasse líquido por R$ 1
A3: iFood | B3: 0.23 | C3: =1-B3
A4: Loja (Retirada) | B4: 0 | C4: =1-B4
A5: Keeta | B5: 0.18 | C5: =1-B5
A7: Líquido por sabor x tamanho
A8: Categoria | B8: Sabor | C8: Tamanho | D8: Bruto iFood | E8: Bruto Loja | F8: Bruto Keeta | G8: Líquido iFood | H8: Líquido Loja | I8: Líquido Keeta
A9: Cabe no seu bolso!!! | B9: Atum especial com mussarela | C9: Brotinho | D9: =IFERROR(INDEX(Comparativo!D:D,MATCH(1,(Comparativo!$B:$B=$B9)*(Comparativo!$C:$C=$C9),0)),"") | E9: =IFERROR(INDEX(Comparativo!E:E,MATCH(1,(Comparativo!$B:$B=$B9)*(Comparativo!$C:$C=$C9),0)),"") | F9: =IFERROR(INDEX(Comparativo!F:F,MATCH(1,(Comparativo!$B:$B=$B9)*(Comparativo!$C:$C=$C9),0)),"") | G9: =IFERROR(D9*$C$3,"") | H9: =IFERROR(E9*$C$4,"") | I9: =IFERROR(F9*$C$5,"")
A10: Cabe no seu bolso!!! | B10: Atum especial com mussarela | C10: Grande | D10: =IFERROR(INDEX(Comparativo!D:D,MATCH(1,(Comparativo!$B:$B=$B10)*(Comparativo!$C:$C=$C10),0)),"") | E10: =IFERROR(INDEX(Comparativo!E:E,MATCH(1,(Comparativo!$B:$B=$B10)*(Comparativo!$C:$C=$C10),0)),"") | F10: =IFERROR(INDEX(Comparativo!F:F,MATCH(1,(Comparativo!$B:$B=$B10)*(Comparativo!$C:$C=$C10),0)),"") | G10: =IFERROR(D10*$C$3,"") | H10: =IFERROR(E10*$C$4,"") | I10: =IFERROR(F10*$C$5,"")
A11: Cabe no seu bolso!!! | B11: Atum ralado com mussarela | C11: Brotinho | D11: =IFERROR(INDEX(Comparativo!D:D,MATCH(1,(Comparativo!$B:$B=$B11)*(Comparativo!$C:$C=$C11),0)),"") | E11: =IFERROR(INDEX(Comparativo!E:E,MATCH(1,(Comparativo!$B:$B=$B11)*(Comparativo!$C:$C=$C11),0)),"") | F11: =IFERROR(INDEX(Comparativo!F:F,MATCH(1,(Comparativo!$B:$B=$B11)*(Comparativo!$C:$C=$C11),0)),"") | G11: =IFERROR(D11*$C$3,"") | H11: =IFERROR(E11*$C$4,"") | I11: =IFERROR(F11*$C$5,"")
A12: Cabe no seu bolso!!! | B12: Atum ralado com mussarela | C12: Grande | D12: =IFERROR(INDEX(Comparativo!D:D,MATCH(1,(Comparativo!$B:$B=$B12)*(Comparativo!$C:$C=$C12),0)),"") | E12: =IFERROR(INDEX(Comparativo!E:E,MATCH(1,(Comparativo!$B:$B=$B12)*(Comparativo!$C:$C=$C12),0)),"") | F12: =IFERROR(INDEX(Comparativo!F:F,MATCH(1,(Comparativo!$B:$B=$B12)*(Comparativo!$C:$C=$C12),0)),"") | G12: =IFERROR(D12*$C$3,"") | H12: =IFERROR(E12*$C$4,"") | I12: =IFERROR(F12*$C$5,"")
A13: Cabe no seu bolso!!! | B13: Pizza Atum | C13: Brotinho | D13: =IFERROR(INDEX(Comparativo!D:D,MATCH(1,(Comparativo!$B:$B=$B13)*(Comparativo!$C:$C=$C13),0)),"") | E13: =IFERROR(INDEX(Comparativo!E:E,MATCH(1,(Comparativo!$B:$B=$B13)*(Comparativo!$C:$C=$C13),0)),"") | F13: =IFERROR(INDEX(Comparativo!F:F,MATCH(1,(Comparativo!$B:$B=$B13)*(Comparativo!$C:$C=$C13),0)),"") | G13: =IFERROR(D13*$C$3,"") | H13: =IFERROR(E13*$C$4,"") | I13: =IFERROR(F13*$C$5,"")
A14: Cabe no seu bolso!!! | B14: Pizza Atum | C14: Grande | D14: =IFERROR(INDEX(Comparativo!D:D,MATCH(1,(Comparativo!$B:$B=$B14)*(Comparativo!$C:$C=$C14),0)),"") | E14: =IFERROR(INDEX(Comparativo!E:E,MATCH(1,(Comparativo!$B:$B=$B14)*(Comparativo!$C:$C=$C14),0)),"") | F14: =IFERROR(INDEX(Comparativo!F:F,MATCH(1,(Comparativo!$B:$B=$B14)*(Comparativo!$C:$C=$C14),0)),"") | G14: =IFERROR(D14*$C$3,"") | H14: =IFERROR(E14*$C$4,"") | I14: =IFERROR(F14*$C$5,"")
A15: Cabe no seu bolso!!! | B15: Pizza Lombo | C15: Brotinho | D15: =IFERROR(INDEX(Comparativo!D:D,MATCH(1,(Comparativo!$B:$B=$B15)*(Comparativo!$C:$C=$C15),0)),"") | E15: =IFERROR(INDEX(Comparativo!E:E,MATCH(1,(Comparativo!$B:$B=$B15)*(Comparativo!$C:$C=$C15),0)),"") | F15: =IFERROR(INDEX(Comparativo!F:F,MATCH(1,(Comparativo!$B:$B=$B15)*(Comparativo!$C:$C=$C15),0)),"") | G15: =IFERROR(D15*$C$3,"") | H15: =IFERROR(E15*$C$4,"") | I15: =IFERROR(F15*$C$5,"")
A16: Cabe no seu bolso!!! | B16: Pizza Lombo | C16: Grande | D16: =IFERROR(INDEX(Comparativo!D:D,MATCH(1,(Comparativo!$B:$B=$B16)*(Comparativo!$C:$C=$C16),0)),"") | E16: =IFERROR(INDEX(Comparativo!E:E,MATCH(1,(Comparativo!$B:$B=$B16)*(Comparativo!$C:$C=$C16),0)),"") | F16: =IFERROR(INDEX(Comparativo!F:F,MATCH(1,(Comparativo!$B:$B=$B16)*(Comparativo!$C:$C=$C16),0)),"") | G16: =IFERROR(D16*$C$3,"") | H16: =IFERROR(E16*$C$4,"") | I16: =IFERROR(F16*$C$5,"")
A17: Cabe no seu bolso!!! | B17: Pizza Mussarela | C17: Brotinho | D17: =IFERROR(INDEX(Comparativo!D:D,MATCH(1,(Comparativo!$B:$B=$B17)*(Comparativo!$C:$C=$C17),0)),"") | E17: =IFERROR(INDEX(Comparativo!E:E,MATCH(1,(Comparativo!$B:$B=$B17)*(Comparativo!$C:$C=$C17),0)),"") | F17: =IFERROR(INDEX(Comparativo!F:F,MATCH(1,(Comparativo!$B:$B=$B17)*(Comparativo!$C:$C=$C17),0)),"") | G17: =IFERROR(D17*$C$3,"") | H17: =IFERROR(E17*$C$4,"") | I17: =IFERROR(F17*$C$5,"")
A18: Cabe no seu bolso!!! | B18: Pizza Mussarela | C18: Grande | D18: =IFERROR(INDEX(Comparativo!D:D,MATCH(1,(Comparativo!$B:$B=$B18)*(Comparativo!$C:$C=$C18),0)),"") | E18: =IFERROR(INDEX(Comparativo!E:E,MATCH(1,(Comparativo!$B:$B=$B18)*(Comparativo!$C:$C=$C18),0)),"") | F18: =IFERROR(INDEX(Comparativo!F:F,MATCH(1,(Comparativo!$B:$B=$B18)*(Comparativo!$C:$C=$C18),0)),"") | G18: =IFERROR(D18*$C$3,"") | H18: =IFERROR(E18*$C$4,"") | I18: =IFERROR(F18*$C$5,"")
A19: Imperdíveis Pizzas salgadas | B19: Pizza Vegetariana | C19: Brotinho | D19: =IFERROR(INDEX(Comparativo!D:D,MATCH(1,(Comparativo!$B:$B=$B19)*(Comparativo!$C:$C=$C19),0)),"") | E19: =IFERROR(INDEX(Comparativo!E:E,MATCH(1,(Comparativo!$B:$B=$B19)*(Comparativo!$C:$C=$C19),0)),"") | F19: =IFERROR(INDEX(Comparativo!F:F,MATCH(1,(Comparativo!$B:$B=$B19)*(Comparativo!$C:$C=$C19),0)),"") | G19: =IFERROR(D19*$C$3,"") | H19: =IFERROR(E19*$C$4,"") | I19: =IFERROR(F19*$C$5,"")
A20: Imperdíveis Pizzas salgadas | B20: Pizza Vegetariana | C20: Grande | D20: =IFERROR(INDEX(Comparativo!D:D,MATCH(1,(Comparativo!$B:$B=$B20)*(Comparativo!$C:$C=$C20),0)),"") | E20: =IFERROR(INDEX(Comparativo!E:E,MATCH(1,(Comparativo!$B:$B=$B20)*(Comparativo!$C:$C=$C20),0)),"") | F20: =IFERROR(INDEX(Comparativo!F:F,MATCH(1,(Comparativo!$B:$B=$B20)*(Comparativo!$C:$C=$C20),0)),"") | G20: =IFERROR(D20*$C$3,"") | H20: =IFERROR(E20*$C$4,"") | I20: =IFERROR(F20*$C$5,"")
... A155: Incrível Sobremesa | B155: Torta Holandesa | C155: Único | D155: =IFERROR(INDEX(Comparativo!D:D,MATCH(1,(Comparativo!$B:$B=$B155)*(Comparativo!$C:$C=$C155),0)),"") | E155: =IFERROR(INDEX(Comparativo!E:E,MATCH(1,(Comparativo!$B:$B=$B155)*(Comparativo!$C:$C=$C155),0)),"") | F155: =IFERROR(INDEX(Comparativo!F:F,MATCH(1,(Comparativo!$B:$B=$B155)*(Comparativo!$C:$C=$C155),0)),"") | G155: =IFERROR(D155*$C$3,"") | H155: =IFERROR(E155*$C$4,"") | I155: =IFERROR(F155*$C$5,"")

Sheet Resumo
A1: Resumo por categoria (preço iFood Brotinho)
A2: Categoria | B2: Nº sabores | C2: Preço médio | D2: Mais barato | E2: Mais caro | F2: Amplitude
A3: Cabe no seu bolso!!! | B3: =COUNTIFS(Dados!$A:$A,A3,Dados!$C:$C,"Brotinho",Dados!$D:$D,"iFood") | C3: =IFERROR(AVERAGEIFS(Dados!$E:$E,Dados!$A:$A,A3,Dados!$C:$C,"Brotinho",Dados!$D:$D,"iFood"),"") | D3: =IFERROR(MINIFS(Dados!$E:$E,Dados!$A:$A,A3,Dados!$C:$C,"Brotinho",Dados!$D:$D,"iFood"),"") | E3: =IFERROR(MAXIFS(Dados!$E:$E,Dados!$A:$A,A3,Dados!$C:$C,"Brotinho",Dados!$D:$D,"iFood"),"") | F3: =IFERROR(E3-D3,"")
A4: Imperdíveis Pizzas salgadas | B4: =COUNTIFS(Dados!$A:$A,A4,Dados!$C:$C,"Brotinho",Dados!$D:$D,"iFood") | C4: =IFERROR(AVERAGEIFS(Dados!$E:$E,Dados!$A:$A,A4,Dados!$C:$C,"Brotinho",Dados!$D:$D,"iFood"),"") | D4: =IFERROR(MINIFS(Dados!$E:$E,Dados!$A:$A,A4,Dados!$C:$C,"Brotinho",Dados!$D:$D,"iFood"),"") | E4: =IFERROR(MAXIFS(Dados!$E:$E,Dados!$A:$A,A4,Dados!$C:$C,"Brotinho",Dados!$D:$D,"iFood"),"") | F4: =IFERROR(E4-D4,"")
A5: As Queridinhas Pizzas Doces | B5: =COUNTIFS(Dados!$A:$A,A5,Dados!$C:$C,"Brotinho",Dados!$D:$D,"iFood") | C5: =IFERROR(AVERAGEIFS(Dados!$E:$E,Dados!$A:$A,A5,Dados!$C:$C,"Brotinho",Dados!$D:$D,"iFood"),"") | D5: =IFERROR(MINIFS(Dados!$E:$E,Dados!$A:$A,A5,Dados!$C:$C,"Brotinho",Dados!$D:$D,"iFood"),"") | E5: =IFERROR(MAXIFS(Dados!$E:$E,Dados!$A:$A,A5,Dados!$C:$C,"Brotinho",Dados!$D:$D,"iFood"),"") | F5: =IFERROR(E5-D5,"")
A6: Incrível Sobremesa | B6: =COUNTIFS(Dados!$A:$A,A6,Dados!$C:$C,"Único",Dados!$D:$D,"iFood") | C6: =IFERROR(AVERAGEIFS(Dados!$E:$E,Dados!$A:$A,A6,Dados!$C:$C,"Único",Dados!$D:$D,"iFood"),"") | D6: =IFERROR(MINIFS(Dados!$E:$E,Dados!$A:$A,A6,Dados!$C:$C,"Único",Dados!$D:$D,"iFood"),"") | E6: =IFERROR(MAXIFS(Dados!$E:$E,Dados!$A:$A,A6,Dados!$C:$C,"Único",Dados!$D:$D,"iFood"),"") | F6: =IFERROR(E6-D6,"")
A8: TOTAL GERAL | B8: =SUM(B3:B7) | C8: =IFERROR(AVERAGEIFS(Dados!$E:$E,Dados!$D:$D,"iFood",Dados!$C:$C,"Brotinho"),"")
A10: Comparação canais (média de todos os sabores)
A11: Plataforma | B11: Preço médio Brotinho | C11: Preço médio Grande
A12: iFood | B12: =IFERROR(AVERAGEIFS(Dados!$E:$E,Dados!$D:$D,A12,Dados!$C:$C,"Brotinho"),"") | C12: =IFERROR(AVERAGEIFS(Dados!$E:$E,Dados!$D:$D,A12,Dados!$C:$C,"Grande"),"")
A13: Loja (Retirada) | B13: =IFERROR(AVERAGEIFS(Dados!$E:$E,Dados!$D:$D,A13,Dados!$C:$C,"Brotinho"),"") | C13: =IFERROR(AVERAGEIFS(Dados!$E:$E,Dados!$D:$D,A13,Dados!$C:$C,"Grande"),"")
A14: Keeta | B14: =IFERROR(AVERAGEIFS(Dados!$E:$E,Dados!$D:$D,A14,Dados!$C:$C,"Brotinho"),"") | C14: =IFERROR(AVERAGEIFS(Dados!$E:$E,Dados!$D:$D,A14,Dados!$C:$C,"Grande"),"")

Sheet Promoções
A1: Promoções e campanhas
A2: Nome | B2: Canal | C2: Sabor / Categoria | D2: Tamanho | E2: Preço normal | F2: Preço promo | G2: Desconto | I2: Preencha as colunas A-F; desconto calculado automaticamente.
G3: =IFERROR(IF(E3=0,"",1-F3/E3),"")
G4: =IFERROR(IF(E4=0,"",1-F4/E4),"")
G5: =IFERROR(IF(E5=0,"",1-F5/E5),"")
G6: =IFERROR(IF(E6=0,"",1-F6/E6),"")
G7: =IFERROR(IF(E7=0,"",1-F7/E7),"")
G8: =IFERROR(IF(E8=0,"",1-F8/E8),"")
G9: =IFERROR(IF(E9=0,"",1-F9/E9),"")
G10: =IFERROR(IF(E10=0,"",1-F10/E10),"")
G11: =IFERROR(IF(E11=0,"",1-F11/E11),"")
G12: =IFERROR(IF(E12=0,"",1-F12/E12),"")
G13: =IFERROR(IF(E13=0,"",1-F13/E13),"")
G14: =IFERROR(IF(E14=0,"",1-F14/E14),"")
... G29: =IFERROR(IF(E29=0,"",1-F29/E29),"")
